class DivTestTryCatch05
{
	public static void main(String[] args) 
	{
		try{
			int a = Integer.parseInt(args[0]);
			int b = Integer.parseInt(args[1]);
			int result = a/b;
			System.out.println("결과:"+result);
		}catch(ArithmeticException e){
			System.out.println("0으로 나눌 수 없습니다.");
		}catch(Exception e){
			System.out.println("두번째수가 0이 아닌 두개의 숫자를 전달해주세요");
		}
	}
}
/*
DivTestTryCatch04.java:12: error: exception ArithmeticException has already been caught
                }catch(ArithmeticException e){
                 ^
1 error
*/